#VRML_SIM R2023b utf8

EXTERNPROTO "https://raw.githubusercontent.com/cyberbotics/webots/R2023b/projects/objects/backgrounds/protos/TexturedBackground.proto"
EXTERNPROTO "https://raw.githubusercontent.com/cyberbotics/webots/R2023b/projects/objects/backgrounds/protos/TexturedBackgroundLight.proto"
EXTERNPROTO "https://raw.githubusercontent.com/cyberbotics/webots/R2023b/projects/objects/floors/protos/CircleArena.proto"

WorldInfo {
}
Viewpoint {
  orientation -0.054158131604701905 0.011926235072899583 -0.9984611468144736 1.648718892561253
  position -0.6900521779628044 0.32929608693112417 0.19569819250096274
}
TexturedBackground {
}
TexturedBackgroundLight {
}
CircleArena {
}
Robot {
  translation -0.7720654702348138 -0.3346808350542369 0.03356652587121255
  rotation 0.6824709248538452 -0.6853007371074427 -0.254158093416544 2.645805499653735
  children [
    Display {
      width 512
      height 256
    }
    Gyro {
      translation 0 -0.01 -0.04
      children [
        Shape {
          appearance PBRAppearance {
            baseColor 1 0 0.498039
          }
          geometry Box {
            size 0.01 0.01 0.01
          }
        }
      ]
    }
    Solid {
      translation 0 0 -0.024
      children [
        DEF holder Shape {
          appearance PBRAppearance {
          }
          geometry Box {
            size 0.045 0.15 0.01
          }
        }
      ]
      name "holder"
      boundingObject USE holder
      physics Physics {
        density -1
        mass 1
      }
    }
    Solid {
      translation 0 0.025 -0.022
      rotation 1 0 0 1.57
      children [
        Shape {
          appearance PBRAppearance {
          }
          geometry Cylinder {
            height 0.01
            radius 0.01
          }
        }
      ]
      name "head"
    }
    DEF wheel1 HingeJoint {
      jointParameters HingeJointParameters {
        position 31133.282467998262
        anchor 0 0 -0.04
      }
      device [
        PositionSensor {
          name "position_sensor1"
        }
        RotationalMotor {
          name "motor1"
        }
      ]
      endPoint DEF wheel1 Solid {
        translation -0.03997280000000001 0 -0.04
        rotation 0.6609708500525312 -0.3563136603539365 0.6604226758872033 3.826869820408306
        children [
          DEF WHEEL Shape {
            appearance PBRAppearance {
              baseColorMap ImageTexture {
                url [
                  "../imgs/1f974.png"
                ]
              }
            }
            geometry Cylinder {
              height 0.02
              radius 0.03
            }
          }
        ]
        name "solid(2)"
        boundingObject USE WHEEL
        physics Physics {
          density -1
          mass 1
        }
        linearVelocity -7.876928204445155e-09 -3.858075113240176e-08 2.1455725517665286e-08
        angularVelocity 0.04142023928502986 9.9999142171413 0.00011714576007524865
      }
    }
    InertialUnit {
      translation 0 0 -0.04
      children [
        Shape {
          appearance PBRAppearance {
            baseColor 0 1 0
          }
          geometry Box {
            size 0.005 0.005 0.005
          }
        }
      ]
      name "imu"
    }
    DEF wheel2 HingeJoint {
      jointParameters HingeJointParameters {
        position 28971.457119070055
        anchor 0 0 -0.04
      }
      device [
        PositionSensor {
          name "position_sensor2"
        }
        RotationalMotor {
          name "motor2"
        }
      ]
      endPoint DEF wheel1 Solid {
        translation 0.03998279999999999 0 -0.04
        rotation -0.45343852754341757 -0.7677851907022452 -0.4526581521165554 4.451809368476734
        children [
          DEF WHEEL Shape {
            appearance PBRAppearance {
              baseColorMap ImageTexture {
                url [
                  "../imgs/1f974.png"
                ]
              }
            }
            geometry Cylinder {
              height 0.02
              radius 0.03
            }
          }
        ]
        name "solid(1)"
        boundingObject USE WHEEL
        physics Physics {
          density -1
          mass 1
        }
        linearVelocity 7.57569163299694e-09 -3.864424974854924e-08 -2.1442251109319857e-08
        angularVelocity 0.041425879609949784 9.999914193735538 0.00012067099349355168
      }
    }
    DEF body Shape {
      appearance PBRAppearance {
        baseColor 0 0 1
      }
      geometry Box {
        size 0.05 0.05 0.07
      }
    }
  ]
  boundingObject USE body
  physics Physics {
    density -1
    mass 10
  }
  controller "ccc"
  controllerArgs [
    ""
  ]
  linearVelocity -8.997976489278813e-11 -2.178647891636853e-08 8.268133652481167e-17
  angularVelocity 5.56302529042725e-07 -2.2975792679714732e-09 3.546004103981661e-08
}
