#VRML_SIM R2023b utf8

EXTERNPROTO "https://raw.githubusercontent.com/cyberbotics/webots/R2023b/projects/objects/backgrounds/protos/TexturedBackground.proto"
EXTERNPROTO "https://raw.githubusercontent.com/cyberbotics/webots/R2023b/projects/objects/backgrounds/protos/TexturedBackgroundLight.proto"
EXTERNPROTO "https://raw.githubusercontent.com/cyberbotics/webots/R2023b/projects/objects/floors/protos/CircleArena.proto"

WorldInfo {
}
Viewpoint {
  orientation -0.06512836444340865 -0.01262847753141329 0.997796982206383 2.3756960484792855
  position 0.6261976722878508 -0.5468277134972205 0.25194443100943836
}
TexturedBackground {
}
TexturedBackgroundLight {
}
CircleArena {
}
Robot {
  translation -0.00016429232600972114 0.027667312744022947 0.060540838152974744
  rotation 9.800059869743203e-05 -0.261407834040444 0.9652284365362254 -3.140877368752801
  children [
    Display {
      width 512
      height 256
    }
    Gyro {
      translation 0 -0.01 -0.04
      children [
        Shape {
          appearance PBRAppearance {
            baseColor 1 0 0.498039
          }
          geometry Box {
            size 0.01 0.01 0.01
          }
        }
      ]
    }
    Solid {
      translation 0 0 -0.024
      children [
        DEF holder Shape {
          appearance PBRAppearance {
          }
          geometry Box {
            size 0.045 0.15 0.01
          }
        }
      ]
      name "holder"
      boundingObject USE holder
      physics Physics {
        density -1
        mass 1
      }
    }
    Solid {
      translation 0 0.025 -0.022
      rotation 1 0 0 1.57
      children [
        Shape {
          appearance PBRAppearance {
          }
          geometry Cylinder {
            height 0.01
            radius 0.01
          }
        }
      ]
      name "head"
    }
    DEF wheel1 HingeJoint {
      jointParameters HingeJointParameters {
        position 26689.28886019842
        anchor 0 0 -0.04
        dampingConstant 0.03
      }
      device [
        PositionSensor {
          name "position_sensor1"
        }
        RotationalMotor {
          name "motor1"
          maxTorque 2
        }
      ]
      endPoint DEF wheel1 Solid {
        translation -0.0399728 0 -0.04
        rotation -0.6784347281884371 -0.2834040461993033 -0.67779677351382 3.6942402654399906
        children [
          DEF WHEEL Shape {
            appearance PBRAppearance {
              baseColorMap ImageTexture {
                url [
                  "../imgs/1f974.png"
                ]
              }
            }
            geometry Cylinder {
              height 0.02
              radius 0.03
            }
          }
        ]
        name "solid(2)"
        boundingObject USE WHEEL
        physics Physics {
          density -1
          mass 1
        }
        linearVelocity -5.215789827844203e-12 7.380585712669583e-12 2.2095438070360843e-16
        angularVelocity -5.922166810717385e-10 -4.0572367920255937e-13 2.2237158089417884e-10
      }
    }
    InertialUnit {
      translation 0 0 -0.04
      children [
        Shape {
          appearance PBRAppearance {
            baseColor 0 1 0
          }
          geometry Box {
            size 0.005 0.005 0.005
          }
        }
      ]
      name "imu"
    }
    DEF wheel2 HingeJoint {
      jointParameters HingeJointParameters {
        position 26856.483500066246
        anchor 0 0 -0.04
        dampingConstant 0.03
      }
      device [
        PositionSensor {
          name "position_sensor2"
        }
        RotationalMotor {
          name "motor2"
          maxTorque 2
        }
      ]
      endPoint DEF wheel1 Solid {
        translation 0.03998279999999986 0 -0.04
        rotation 0.7008342385817854 -0.1359983816458622 0.7002398233613936 3.412818073940193
        children [
          DEF WHEEL Shape {
            appearance PBRAppearance {
              baseColorMap ImageTexture {
                url [
                  "../imgs/1f974.png"
                ]
              }
            }
            geometry Cylinder {
              height 0.02
              radius 0.03
            }
          }
        ]
        name "solid(1)"
        boundingObject USE WHEEL
        physics Physics {
          density -1
          mass 1
        }
        linearVelocity -5.2032476067007295e-12 -1.039997122399958e-11 -2.0693192597458523e-16
        angularVelocity 7.42550730187164e-10 5.195709384708825e-13 2.2237688507306992e-10
      }
    }
    DEF body Shape {
      appearance PBRAppearance {
        baseColor 0 0 1
      }
      geometry Box {
        size 0.05 0.05 0.07
      }
    }
  ]
  name "Dormily"
  boundingObject USE body
  physics Physics {
    density -1
    mass 10
  }
  controller "ccc"
  controllerArgs [
    ""
  ]
  linearVelocity -9.656638431115534e-13 -1.5057369221402773e-12 4.1340668262405834e-16
  angularVelocity 6.90291318655197e-15 -2.6675295938923417e-15 2.22380018751767e-10
}
