#VRML_SIM R2023b utf8

EXTERNPROTO "https://raw.githubusercontent.com/cyberbotics/webots/R2023b/projects/objects/backgrounds/protos/TexturedBackground.proto"
EXTERNPROTO "https://raw.githubusercontent.com/cyberbotics/webots/R2023b/projects/objects/backgrounds/protos/TexturedBackgroundLight.proto"
EXTERNPROTO "https://raw.githubusercontent.com/cyberbotics/webots/R2023b/projects/objects/floors/protos/CircleArena.proto"

WorldInfo {
}
Viewpoint {
  orientation -0.21768187588718885 0.9455591081373621 0.24193506138778406 0.4010579885677348
  position 0.019092790671836724 0.8474948632200722 0.2628221354899394
}
TexturedBackground {
}
TexturedBackgroundLight {
}
CircleArena {
}
Robot {
  translation 0.3337386940225478 0.8672302282865293 0.06607352949220992
  rotation 0.9640488589810146 -0.26503071430018393 0.019196822001006246 -2.369259620721458
  children [
    Display {
    }
    Gyro {
      translation 0 -0.01 -0.04
      children [
        Shape {
          appearance PBRAppearance {
            baseColor 1 0 0.498039
          }
          geometry Box {
            size 0.01 0.01 0.01
          }
        }
      ]
    }
    Solid {
      translation 0 0 0.024
      children [
        DEF holder Shape {
          appearance PBRAppearance {
          }
          geometry Box {
            size 0.045 0.15 0.01
          }
        }
      ]
      name "holder"
      boundingObject USE holder
      physics Physics {
        density -1
        mass 1
      }
    }
    Solid {
      translation 0 0.025 -0.022
      rotation 1 0 0 1.57
      children [
        Shape {
          appearance PBRAppearance {
          }
          geometry Cylinder {
            height 0.01
            radius 0.01
          }
        }
      ]
      name "head"
    }
    HingeJoint {
      jointParameters HingeJointParameters {
        position 9512.251508561634
        anchor 0 0 0.04
      }
      device [
        RotationalMotor {
          name "motor1"
        }
      ]
      endPoint DEF wheel1 Solid {
        translation -0.03997280000000001 0 0.04
        rotation -0.700291454515019 0.14154561100677804 -0.6996832988845433 2.8599626095566224
        children [
          DEF WHEEL Shape {
            appearance PBRAppearance {
              baseColorMap ImageTexture {
                url [
                  "../imgs/1f974.png"
                ]
              }
            }
            geometry Cylinder {
              height 0.02
              radius 0.03
            }
          }
        ]
        name "solid(2)"
        boundingObject USE WHEEL
        physics Physics {
          density -1
          mass 1
        }
        linearVelocity -0.00035262288066873046 -0.0011841492065329839 0.001658508653151898
        angularVelocity 8.812241121756655 -4.52947953506299 -1.532612512309302
      }
    }
    InertialUnit {
      translation 0 0 -0.04
      children [
        Shape {
          appearance PBRAppearance {
            baseColor 0 1 0
          }
          geometry Box {
            size 0.005 0.005 0.005
          }
        }
      ]
      name "imu"
    }
    HingeJoint {
      jointParameters HingeJointParameters {
        position 7350.437002703298
        anchor 0 0 0.04
      }
      device [
        RotationalMotor {
          name "motor2"
        }
      ]
      endPoint DEF wheel1 Solid {
        translation 0.0399828 0 0.04
        rotation 0.23453520777047493 0.9435538774491274 0.23387885040502768 1.628043148036114
        children [
          DEF WHEEL Shape {
            appearance PBRAppearance {
              baseColorMap ImageTexture {
                url [
                  "../imgs/1f974.png"
                ]
              }
            }
            geometry Cylinder {
              height 0.02
              radius 0.03
            }
          }
        ]
        name "solid(1)"
        boundingObject USE WHEEL
        physics Physics {
          density -1
          mass 1
        }
        linearVelocity -0.00029303940748160725 -0.0010002407579572685 0.001457638480247112
        angularVelocity 8.812243188515035 -4.5294743461693905 -1.5326159678509421
      }
    }
    DEF body Shape {
      appearance PBRAppearance {
        baseColor 0 0 1
      }
      geometry Box {
        size 0.05 0.05 0.07
      }
    }
  ]
  boundingObject USE body
  physics Physics {
    density -1
    mass 10
  }
  controller "ccc"
  controllerArgs [
    ""
  ]
  linearVelocity -0.0006246861204248702 -0.0017373969705191538 0.000867433495683271
  angularVelocity 0.02434149393554145 -0.00964466954782045 -0.001628212539508123
}
