#VRML_SIM R2023b utf8

EXTERNPROTO "https://raw.githubusercontent.com/cyberbotics/webots/R2023b/projects/objects/backgrounds/protos/TexturedBackground.proto"
EXTERNPROTO "https://raw.githubusercontent.com/cyberbotics/webots/R2023b/projects/objects/backgrounds/protos/TexturedBackgroundLight.proto"
EXTERNPROTO "https://raw.githubusercontent.com/cyberbotics/webots/R2023b/projects/objects/floors/protos/CircleArena.proto"

WorldInfo {
}
Viewpoint {
  orientation 0.754746308825201 0.5422756184283115 -0.36918174788703556 6.19554666025328
  position -1.7660843729216944 -0.163524602513389 0.16136871407141967
}
TexturedBackground {
}
TexturedBackgroundLight {
}
CircleArena {
  radius 3
}
Robot {
  translation 0 0 0.08
  rotation -1.512458315712126e-05 -0.012822909089422423 0.9999177830070488 -3.1397403683221623
  children [
    Display {
      width 512
      height 256
    }
    Gyro {
      translation 0 -0.01 -0.04
      children [
        Shape {
          appearance PBRAppearance {
            baseColor 1 0 0.498039
          }
          geometry Box {
            size 0.01 0.01 0.01
          }
        }
      ]
    }
    Solid {
      translation 0 0 -0.024
      children [
        DEF holder Shape {
          appearance PBRAppearance {
          }
          geometry Box {
            size 0.045 0.15 0.01
          }
        }
      ]
      name "holder"
      boundingObject USE holder
      physics Physics {
        density -1
        mass 1
      }
    }
    Solid {
      translation 0 0.025 0.022
      rotation 1 0 0 1.57
      children [
        DEF head Shape {
          appearance PBRAppearance {
          }
          geometry Cylinder {
            height 0.01
            radius 0.01
          }
        }
      ]
      name "head"
      boundingObject USE head
      physics Physics {
        density -1
        mass 1
      }
    }
    DEF wheel1 HingeJoint {
      jointParameters HingeJointParameters {
        position 26589.911936294488
        anchor 0 0 -0.04
        dampingConstant 0.03
      }
      device [
        PositionSensor {
          name "position_sensor1"
        }
        RotationalMotor {
          name "motor1"
          maxTorque 2
        }
      ]
      endPoint DEF wheel1 Solid {
        translation -0.0399727034196211 -0.00019846575390799315 -0.04030847261596124
        rotation -0.7015701539232205 0.12825637211330734 -0.7009633529197382 2.886039377635774
        children [
          DEF WHEEL Shape {
            appearance PBRAppearance {
              baseColorMap ImageTexture {
                url [
                  "../imgs/1f974.png"
                ]
              }
            }
            geometry Cylinder {
              height 0.02
              radius 0.03
            }
          }
        ]
        name "solid(2)"
        boundingObject USE WHEEL
        physics Physics {
          density -1
          mass 1
        }
      }
    }
    InertialUnit {
      translation 0 0 -0.04
      children [
        Shape {
          appearance PBRAppearance {
            baseColor 0 1 0
          }
          geometry Box {
            size 0.005 0.005 0.005
          }
        }
      ]
      name "imu"
    }
    DEF wheel2 HingeJoint {
      jointParameters HingeJointParameters {
        position 26757.103373320446
        anchor 0 0 -0.04
        dampingConstant 0.03
      }
      device [
        PositionSensor {
          name "position_sensor2"
        }
        RotationalMotor {
          name "motor2"
          maxTorque 2
        }
      ]
      endPoint DEF wheel1 Solid {
        translation 0.039982696409220184 -0.00019774387123535302 -0.04031036564853417
        rotation -0.5844065843809322 0.5632832561296346 -0.5841069401198798 2.1144058748649925
        children [
          DEF WHEEL Shape {
            appearance PBRAppearance {
              baseColorMap ImageTexture {
                url [
                  "../imgs/1f974.png"
                ]
              }
            }
            geometry Cylinder {
              height 0.02
              radius 0.03
            }
          }
        ]
        name "solid(1)"
        boundingObject USE WHEEL
        physics Physics {
          density -1
          mass 1
        }
      }
    }
    DEF body Shape {
      appearance PBRAppearance {
        baseColor 0 0 1
      }
      geometry Box {
        size 0.05 0.05 0.07
      }
    }
  ]
  name "Dormily"
  boundingObject USE body
  physics Physics {
    density -1
    mass 10
  }
  controller "ccc"
  controllerArgs [
    ""
  ]
}
