#VRML_SIM R2023b utf8

EXTERNPROTO "https://raw.githubusercontent.com/cyberbotics/webots/R2023b/projects/objects/backgrounds/protos/TexturedBackground.proto"
EXTERNPROTO "https://raw.githubusercontent.com/cyberbotics/webots/R2023b/projects/objects/backgrounds/protos/TexturedBackgroundLight.proto"
EXTERNPROTO "https://raw.githubusercontent.com/cyberbotics/webots/R2023b/projects/objects/floors/protos/CircleArena.proto"

WorldInfo {
}
Viewpoint {
  orientation 0.22665003182828955 -0.10960015694119173 -0.9677900436926915 4.342074265438079
  position -0.6581313614606281 -1.0005605899040988 0.5093262426878923
}
TexturedBackground {
}
TexturedBackgroundLight {
}
CircleArena {
}
Robot {
  translation -0.8697196715897882 -0.3812574820555541 0.06044305145311368
  rotation 0.69587882568451 -0.6946896211076792 0.18209610179577349 -2.7903033667064583
  children [
    Display {
      width 128
    }
    Gyro {
      translation 0 -0.01 -0.04
      children [
        Shape {
          appearance PBRAppearance {
            baseColor 1 0 0.498039
          }
          geometry Box {
            size 0.01 0.01 0.01
          }
        }
      ]
    }
    Solid {
      translation 0 0 0.024
      children [
        DEF holder Shape {
          appearance PBRAppearance {
          }
          geometry Box {
            size 0.045 0.15 0.01
          }
        }
      ]
      name "holder"
      boundingObject USE holder
      physics Physics {
        density -1
        mass 1
      }
    }
    Solid {
      translation 0 0.025 -0.022
      rotation 1 0 0 1.57
      children [
        Shape {
          appearance PBRAppearance {
          }
          geometry Cylinder {
            height 0.01
            radius 0.01
          }
        }
      ]
      name "head"
    }
    HingeJoint {
      jointParameters HingeJointParameters {
        position 12262.3809961845
        anchor 0 0 0.04
      }
      device [
        RotationalMotor {
          name "motor1"
        }
      ]
      endPoint DEF wheel1 Solid {
        translation -0.039972800000000024 0 0.04
        rotation -0.5897232210774088 -0.5524025839360295 -0.5891331833998857 4.151615237054445
        children [
          DEF WHEEL Shape {
            appearance PBRAppearance {
              baseColorMap ImageTexture {
                url [
                  "../imgs/1f974.png"
                ]
              }
            }
            geometry Cylinder {
              height 0.02
              radius 0.03
            }
          }
        ]
        name "solid(2)"
        boundingObject USE WHEEL
        physics Physics {
          density -1
          mass 1
        }
        linearVelocity -2.0846349911948805e-05 6.053757595643096e-05 -1.081418349258469e-06
        angularVelocity -5.8944405731726005e-05 -9.999730634068044 0.06646959065341213
      }
    }
    InertialUnit {
      translation 0 0 -0.04
      children [
        Shape {
          appearance PBRAppearance {
            baseColor 0 1 0
          }
          geometry Box {
            size 0.005 0.005 0.005
          }
        }
      ]
      name "imu"
    }
    HingeJoint {
      jointParameters HingeJointParameters {
        position 10100.566152658119
        anchor 0 0 0.04
      }
      device [
        RotationalMotor {
          name "motor2"
        }
      ]
      endPoint DEF wheel1 Solid {
        translation 0.03998279999999999 0 0.04
        rotation -0.5462364478588859 0.6352087717974116 -0.5460179111184271 2.0085695597867983
        children [
          DEF WHEEL Shape {
            appearance PBRAppearance {
              baseColorMap ImageTexture {
                url [
                  "../imgs/1f974.png"
                ]
              }
            }
            geometry Cylinder {
              height 0.02
              radius 0.03
            }
          }
        ]
        name "solid(1)"
        boundingObject USE WHEEL
        physics Physics {
          density -1
          mass 1
        }
        linearVelocity -2.0886133435169624e-05 6.055170213033997e-05 -1.32672805693807e-06
        angularVelocity -0.00010209639252413599 -9.999729404711651 0.06645924156654284
      }
    }
    DEF body Shape {
      appearance PBRAppearance {
        baseColor 0 0 1
      }
      geometry Box {
        size 0.05 0.05 0.07
      }
    }
  ]
  boundingObject USE body
  physics Physics {
    density -1
    mass 10
  }
  controller "ccc"
  controllerArgs [
    ""
  ]
  linearVelocity -1.969587895634752e-05 6.036230553809219e-05 -5.772060681424178e-07
  angularVelocity 6.48475425738123e-06 3.509297436258156e-05 -1.832594690116904e-06
}
