#VRML_SIM R2023b utf8

EXTERNPROTO "https://raw.githubusercontent.com/cyberbotics/webots/R2023b/projects/objects/backgrounds/protos/TexturedBackground.proto"
EXTERNPROTO "https://raw.githubusercontent.com/cyberbotics/webots/R2023b/projects/objects/backgrounds/protos/TexturedBackgroundLight.proto"
EXTERNPROTO "https://raw.githubusercontent.com/cyberbotics/webots/R2023b/projects/objects/floors/protos/CircleArena.proto"

WorldInfo {
}
Viewpoint {
  orientation 0.20280737500161813 -0.010984529164945864 -0.9791570398888922 3.5865514986905502
  position 0.6241692476624413 -0.265501897106643 0.36139456760435085
}
TexturedBackground {
}
TexturedBackgroundLight {
}
CircleArena {
  radius 3
}
Robot {
  translation -0.00019266033915423165 0.06260228418973848 0.06481232642494687
  rotation -5.794853617881713e-06 -1.6692190015555484e-05 0.9999999998438953 -3.1413580955463583
  children [
    Display {
      width 512
      height 256
    }
    Gyro {
      translation 0 -0.01 -0.04
      children [
        Shape {
          appearance PBRAppearance {
            baseColor 1 0 0.498039
          }
          geometry Box {
            size 0.01 0.01 0.01
          }
        }
      ]
    }
    Solid {
      translation 0 0 -0.024
      children [
        DEF holder Shape {
          appearance PBRAppearance {
          }
          geometry Box {
            size 0.045 0.15 0.01
          }
        }
      ]
      name "holder"
      boundingObject USE holder
      physics Physics {
        density -1
        mass 1
      }
    }
    Solid {
      translation 0 0.025 -0.022
      rotation 1 0 0 1.57
      children [
        Shape {
          appearance PBRAppearance {
          }
          geometry Cylinder {
            height 0.01
            radius 0.01
          }
        }
      ]
      name "head"
    }
    DEF wheel1 HingeJoint {
      jointParameters HingeJointParameters {
        position 26689.290034361547
        anchor 0 0 -0.04
        dampingConstant 0.03
      }
      device [
        PositionSensor {
          name "position_sensor1"
        }
        RotationalMotor {
          name "motor1"
          maxTorque 2
        }
      ]
      endPoint DEF wheel1 Solid {
        translation -0.039972799999999996 0 -0.04
        rotation -0.6785245054693982 -0.2829741342885866 -0.6778865205925944 3.693443619675575
        children [
          DEF WHEEL Shape {
            appearance PBRAppearance {
              baseColorMap ImageTexture {
                url [
                  "../imgs/1f974.png"
                ]
              }
            }
            geometry Cylinder {
              height 0.02
              radius 0.03
            }
          }
        ]
        name "solid(2)"
        boundingObject USE WHEEL
        physics Physics {
          density -1
          mass 1
        }
        linearVelocity 1.217248321994144e-09 -5.991244732241372e-06 2.743252024479883e-10
        angularVelocity 0.00019987522241879412 3.9663979550337205e-08 1.6288436145151047e-07
      }
    }
    InertialUnit {
      translation 0 0 -0.04
      children [
        Shape {
          appearance PBRAppearance {
            baseColor 0 1 0
          }
          geometry Box {
            size 0.005 0.005 0.005
          }
        }
      ]
      name "imu"
    }
    DEF wheel2 HingeJoint {
      jointParameters HingeJointParameters {
        position 26856.48603577813
        anchor 0 0 -0.04
        dampingConstant 0.03
      }
      device [
        PositionSensor {
          name "position_sensor2"
        }
        RotationalMotor {
          name "motor2"
          maxTorque 2
        }
      ]
      endPoint DEF wheel1 Solid {
        translation 0.03998279999999986 0 -0.04
        rotation 0.7007459084474392 -0.13690272691659447 0.7001519943247848 3.414595075785009
        children [
          DEF WHEEL Shape {
            appearance PBRAppearance {
              baseColorMap ImageTexture {
                url [
                  "../imgs/1f974.png"
                ]
              }
            }
            geometry Cylinder {
              height 0.02
              radius 0.03
            }
          }
        ]
        name "solid(1)"
        boundingObject USE WHEEL
        physics Physics {
          density -1
          mass 1
        }
        linearVelocity 1.164144429406453e-09 -6.003997523351124e-06 -2.9317720832332433e-10
        angularVelocity 0.00020030374700333255 3.9767072545809547e-08 1.6071157214787154e-07
      }
    }
    DEF body Shape {
      appearance PBRAppearance {
        baseColor 0 0 1
      }
      geometry Box {
        size 0.05 0.05 0.07
      }
    }
  ]
  name "Dormily"
  boundingObject USE body
  physics Physics {
    density -1
    mass 10
  }
  controller "ccc"
  controllerArgs [
    ""
  ]
  linearVelocity 8.918530982161454e-10 -5.894440384674024e-06 -8.368322762015107e-11
  angularVelocity -2.7032298718273935e-06 -7.875434692331892e-09 1.5944788385707798e-07
}
